Traceback (most recent call last):
  File "C:\Users\arajen\Anaconda3\envs\jbook\lib\site-packages\jupyter_cache\executors\utils.py", line 56, in single_nb_execution
    record_timing=False,
  File "C:\Users\arajen\Anaconda3\envs\jbook\lib\site-packages\nbclient\client.py", line 1117, in execute
    return NotebookClient(nb=nb, resources=resources, km=km, **kwargs).execute()
  File "C:\Users\arajen\Anaconda3\envs\jbook\lib\site-packages\nbclient\util.py", line 78, in wrapped
    return just_run(coro(*args, **kwargs))
  File "C:\Users\arajen\Anaconda3\envs\jbook\lib\site-packages\nbclient\util.py", line 57, in just_run
    return loop.run_until_complete(coro)
  File "C:\Users\arajen\Anaconda3\envs\jbook\lib\asyncio\base_events.py", line 587, in run_until_complete
    return future.result()
  File "C:\Users\arajen\Anaconda3\envs\jbook\lib\site-packages\nbclient\client.py", line 559, in async_execute
    cell, index, execution_count=self.code_cells_executed + 1
  File "C:\Users\arajen\Anaconda3\envs\jbook\lib\site-packages\nbclient\client.py", line 862, in async_execute_cell
    self._check_raise_for_error(cell, exec_reply)
  File "C:\Users\arajen\Anaconda3\envs\jbook\lib\site-packages\nbclient\client.py", line 765, in _check_raise_for_error
    raise CellExecutionError.from_cell_and_msg(cell, exec_reply_content)
nbclient.exceptions.CellExecutionError: An error occurred while executing the following cell:
------------------
import pandas as pd
import numpy as np
import matplotlib.pyplot as plt
import matplotlib.dates as mdates
import datetime as dt
import pvlib

data_path = 'https://www.dropbox.com/s/qd8aw2ug8s7dq4u/solar_irradiance_dtu_2019_extended.csv?dl=1'

df = pd.read_csv(data_path, index_col=[0], parse_dates=[0])
df.index = df.index.tz_localize('UTC')  # Make index timezone aware
original_entries = df.shape[0]

df.head()  # Print the first five lines of the DataFrame
------------------

[1;31m---------------------------------------------------------------------------[0m
[1;31mModuleNotFoundError[0m                       Traceback (most recent call last)
[1;32m~\AppData\Local\Temp/ipykernel_11308/3120581524.py[0m in [0;36m<module>[1;34m[0m
[1;32m----> 1[1;33m [1;32mimport[0m [0mpandas[0m [1;32mas[0m [0mpd[0m[1;33m[0m[1;33m[0m[0m
[0m[0;32m      2[0m [1;32mimport[0m [0mnumpy[0m [1;32mas[0m [0mnp[0m[1;33m[0m[1;33m[0m[0m
[0;32m      3[0m [1;32mimport[0m [0mmatplotlib[0m[1;33m.[0m[0mpyplot[0m [1;32mas[0m [0mplt[0m[1;33m[0m[1;33m[0m[0m
[0;32m      4[0m [1;32mimport[0m [0mmatplotlib[0m[1;33m.[0m[0mdates[0m [1;32mas[0m [0mmdates[0m[1;33m[0m[1;33m[0m[0m
[0;32m      5[0m [1;32mimport[0m [0mdatetime[0m [1;32mas[0m [0mdt[0m[1;33m[0m[1;33m[0m[0m

[1;31mModuleNotFoundError[0m: No module named 'pandas'
ModuleNotFoundError: No module named 'pandas'

